Traceback (most recent call last):
  File "/Users/fuzzbin/.pyenv/versions/3.10.4/lib/python3.10/site-packages/jupyter_cache/executors/utils.py", line 51, in single_nb_execution
    executenb(
  File "/Users/fuzzbin/.pyenv/versions/3.10.4/lib/python3.10/site-packages/nbclient/client.py", line 1204, in execute
    return NotebookClient(nb=nb, resources=resources, km=km, **kwargs).execute()
  File "/Users/fuzzbin/.pyenv/versions/3.10.4/lib/python3.10/site-packages/nbclient/util.py", line 84, in wrapped
    return just_run(coro(*args, **kwargs))
  File "/Users/fuzzbin/.pyenv/versions/3.10.4/lib/python3.10/site-packages/nbclient/util.py", line 62, in just_run
    return loop.run_until_complete(coro)
  File "/Users/fuzzbin/.pyenv/versions/3.10.4/lib/python3.10/asyncio/base_events.py", line 646, in run_until_complete
    return future.result()
  File "/Users/fuzzbin/.pyenv/versions/3.10.4/lib/python3.10/site-packages/nbclient/client.py", line 663, in async_execute
    await self.async_execute_cell(
  File "/Users/fuzzbin/.pyenv/versions/3.10.4/lib/python3.10/site-packages/nbclient/client.py", line 965, in async_execute_cell
    await self._check_raise_for_error(cell, cell_index, exec_reply)
  File "/Users/fuzzbin/.pyenv/versions/3.10.4/lib/python3.10/site-packages/nbclient/client.py", line 862, in _check_raise_for_error
    raise CellExecutionError.from_cell_and_msg(cell, exec_reply_content)
nbclient.exceptions.CellExecutionError: An error occurred while executing the following cell:
------------------
import sqlite3

# Lager en databsefil
con = sqlite3.connect("demo.db")

# Oppretter en tilkobling til databasen
cur = con.cursor()

# Lager en ny tabell
cur.execute("CREATE TABLE person(p_nr integer, navn text, yrke text, myndig boolean)")

# Legger inn en rad med data
cur.execute("INSERT INTO person VALUES (1, 'Tom Jarle', 'l√¶rer', 'TRUE')")
cur.execute("INSERT INTO person VALUES (2, 'Eva', 'l√¶rer', 'TRUE')")

# Save (commit) the changes
con.commit()

# Skriver ut alle datya
for row in cur.execute("SELECT * FROM person"):
        print(row)

# Lukker forbindelsen
con.close()


------------------

[0;31m---------------------------------------------------------------------------[0m
[0;31mOperationalError[0m                          Traceback (most recent call last)
Input [0;32mIn [1][0m, in [0;36m<cell line: 10>[0;34m()[0m
[1;32m      7[0m cur [38;5;241m=[39m con[38;5;241m.[39mcursor()
[1;32m      9[0m [38;5;66;03m# Lager en ny tabell[39;00m
[0;32m---> 10[0m [43mcur[49m[38;5;241;43m.[39;49m[43mexecute[49m[43m([49m[38;5;124;43m"[39;49m[38;5;124;43mCREATE TABLE person(p_nr integer, navn text, yrke text, myndig boolean)[39;49m[38;5;124;43m"[39;49m[43m)[49m
[1;32m     12[0m [38;5;66;03m# Legger inn en rad med data[39;00m
[1;32m     13[0m cur[38;5;241m.[39mexecute([38;5;124m"[39m[38;5;124mINSERT INTO person VALUES (1, [39m[38;5;124m'[39m[38;5;124mTom Jarle[39m[38;5;124m'[39m[38;5;124m, [39m[38;5;124m'[39m[38;5;124ml√¶rer[39m[38;5;124m'[39m[38;5;124m, [39m[38;5;124m'[39m[38;5;124mTRUE[39m[38;5;124m'[39m[38;5;124m)[39m[38;5;124m"[39m)

[0;31mOperationalError[0m: table person already exists
OperationalError: table person already exists

