Traceback (most recent call last):
  File "/Users/fuzzbin/.pyenv/versions/3.9.4/lib/python3.9/site-packages/jupyter_cache/executors/utils.py", line 51, in single_nb_execution
    executenb(
  File "/Users/fuzzbin/.pyenv/versions/3.9.4/lib/python3.9/site-packages/nbclient/client.py", line 1112, in execute
    return NotebookClient(nb=nb, resources=resources, km=km, **kwargs).execute()
  File "/Users/fuzzbin/.pyenv/versions/3.9.4/lib/python3.9/site-packages/nbclient/util.py", line 74, in wrapped
    return just_run(coro(*args, **kwargs))
  File "/Users/fuzzbin/.pyenv/versions/3.9.4/lib/python3.9/site-packages/nbclient/util.py", line 53, in just_run
    return loop.run_until_complete(coro)
  File "/Users/fuzzbin/.pyenv/versions/3.9.4/lib/python3.9/asyncio/base_events.py", line 642, in run_until_complete
    return future.result()
  File "/Users/fuzzbin/.pyenv/versions/3.9.4/lib/python3.9/site-packages/nbclient/client.py", line 553, in async_execute
    await self.async_execute_cell(
  File "/Users/fuzzbin/.pyenv/versions/3.9.4/lib/python3.9/site-packages/nbclient/client.py", line 857, in async_execute_cell
    self._check_raise_for_error(cell, exec_reply)
  File "/Users/fuzzbin/.pyenv/versions/3.9.4/lib/python3.9/site-packages/nbclient/client.py", line 760, in _check_raise_for_error
    raise CellExecutionError.from_cell_and_msg(cell, exec_reply_content)
nbclient.exceptions.CellExecutionError: An error occurred while executing the following cell:
------------------
import sqlite3

# Lager en databsefil
con = sqlite3.connect("demo.db")

# Oppretter en tilkobling til databasen
cur = con.cursor()

# Lager en ny tabell
cur.execute("CREATE TABLE person(p_nr integer, navn text, yrke text, myndig boolean)")

# Legger inn en rad med data
cur.execute("INSERT INTO person VALUES (1, 'Tom Jarle', 'l√¶rer', 'TRUE')")
cur.execute("INSERT INTO person VALUES (2, 'Eva', 'l√¶rer', 'TRUE')")

# Save (commit) the changes
con.commit()

# Skriver ut alle datya
for row in cur.execute("SELECT * FROM person"):
        print(row)

# Lukker forbindelsen
con.close()


------------------

[0;31m---------------------------------------------------------------------------[0m
[0;31mOperationalError[0m                          Traceback (most recent call last)
[0;32m<ipython-input-1-53333f1defe6>[0m in [0;36m<module>[0;34m[0m
[1;32m      8[0m [0;34m[0m[0m
[1;32m      9[0m [0;31m# Lager en ny tabell[0m[0;34m[0m[0;34m[0m[0;34m[0m[0m
[0;32m---> 10[0;31m [0mcur[0m[0;34m.[0m[0mexecute[0m[0;34m([0m[0;34m"CREATE TABLE person(p_nr integer, navn text, yrke text, myndig boolean)"[0m[0;34m)[0m[0;34m[0m[0;34m[0m[0m
[0m[1;32m     11[0m [0;34m[0m[0m
[1;32m     12[0m [0;31m# Legger inn en rad med data[0m[0;34m[0m[0;34m[0m[0;34m[0m[0m

[0;31mOperationalError[0m: table person already exists
OperationalError: table person already exists

